Workbook

Sheet SEGUIMIENTO COMPRAS TRIBE
A1: STOCK | B1: CLIENTE | C1: ITEM | D1: CANTIDAD | E1: LINK DE COMPRA | F1: VALOR PRESUPUESTADO | G1: FECHA DE COMPRA | H1: VALOR DE COMPRA | I1: VALOR DEBITADO | J1: TAX 4% | K1: COSTO ENVIO | L1: PESO | M1: ITEM STATUS | N1: SALDADO | O1: ASIGNADO | P1: GANANCIA | Q1: SALDADO A ? | R1: ✅ 🇺🇸 💵 | S1: TRACKING | T1: OBSERVACIONES
A2: NO | B2: abel | C2: CHAPON WRX | D2: 1 | E2: https://www.amazon.com/gp/product/B00PV6T5U4/ref=ppx_yo_dt_b_asin_title_o03_s00?ie=UTF8&psc=1 | F2: 600 | G2: 45009 | H2: 183.51 | I2: 185.35 | J2: =I2+(I2*0.04) -> 192.764 | K2: 160 | M2: DONE | N2: SI | P2: =F2-(J2+K2) -> 247.236 | R2: SI | S2: UPS: 1ZVE87110302402577 | T2: ENTREGADO A CLIENTE
A3: NO | B3: abel | C3: GUARDAPLAST WRX | D3: 1 | E3: https://www.ebay.com/itm/371496693838 | F3: 210 | G3: 45014 | H3: 32.2 | I3: 32.52 | J3: =I3+(I3*0.04) -> 33.8208 | K3: 40 | M3: DONE | N3: SI | P3: =F3-(J3+K3) -> 136.1792 | R3: SI | S3: FedEx: 396389639118 | T3: ENTREGADO A CLIENTE
A4: NO | B4: yani | C4: BOMBA WALBRO | D4: 1 | F4: 265 | H4: 158.9 | I4: 160.49 | J4: =I4+(I4*0.04) -> 166.9096 | K4: 40 | M4: DONE | N4: SI | P4: =F4-(J4+K4) -> 58.0904 | R4: SI | S4: TBA305962486126 | T4: ENTREGADO A CLIENTE
A5: NO | B5: alfredo si | C5: PASTILLAS HAWK | D5: 1 | F5: 55 | I5: 0 | J5: 0 | K5: 40 | M5: DONE | N5: SI | P5: =F5-(J5+K5) -> 15 | R5: SI | S5: FedEx: 396305659584 | T5: ENTREGADO A CLIENTE
A6: NO | B6: NERF | C6: TECLADO | D6: 1 | F6: 0 | J6: =I6+(I6*0.04) -> 0 | K6: 0 | M6: DONE | N6: SI | P6: =F6-(J6+K6) -> 0 | R6: SI | S6: UPS: 1ZA533G60318105439 | T6: ENTREGADO A CLIENTE
A7: NO | B7: abel | C7: PASARUEDAS WRX | D7: 1 | E7: https://www.amazon.com/gp/product/B07F1C9MFJ/ref=ppx_yo_dt_b_asin_title_o04_s00?ie=UTF8&psc=1 | F7: 90 | G7: 45009 | H7: 42.75 | I7: 43.18 | J7: =I7+(I7*0.04) -> 44.9072 | K7: 40 | M7: DONE | N7: SI | P7: =F7-(J7+K7) -> 5.0928 | R7: SI | S7: FEDEX: 396202387161 | T7: ENTREGADO A CLIENTE
A8: NO | B8: Migale | C8: OPTICA VOLVO DER | D8: 1 | E8: https://www.ebay.com/itm/175564026454?hash=item28e06e7256:g:JvoAAOSw-7Zj5CHH&amdata=enc%3AAQAHAAAAoIXUlg1UNk7TbYe3FabkWPJcOXfJjxUdU08uXWu1bYnwPC%2F23lQcUalfPDXA%2F0bT7Dz8P784RjZYuWHUWf3%2FRm9HK5lbZH%2Bpvp4UpWfQ6acBIQlrqP6gYfBB82zF0Jk0tSlwsMADKQudHIX1zkphqSG%2Fu1alGJE6zwIH1wHmaGDwTtkRuLmMbjumRFo4AXXWtp2rXLDnyNCurdnkhCTrurY%3D%7Ctkp%3ABk9SR_zgqLTJYQ | F8: 900 | H8: 426.91 | I8: 431.18 | J8: =I8+(I8*0.04) -> 448.4272 | K8: 225 | M8: DONE | N8: SI | P8: =F8-(J8+K8) -> 226.5728 | R8: SI | S8: FedEx: 396575849146 | T8: ENTREGADO A CLIENTE
A9: NO | B9: Migale | C9: OPTICA VOLVO IZQ | D9: 1 | E9: https://www.ebay.com/itm/404223900795?hash=item5e1d9f3c7b:g:5YgAAOSwMyhkJdSM&amdata=enc%3AAQAHAAAA8FSz39KtRB%2BPktdf2yt1G8hS8rRdtTIp4RLsIvLQuULpWtmk1v90Xi%2FEB4ii2lYGvs4cGUkO0HRK1lPAO34hmV5OUoiPnYQLJaqewa5lB3ZXz%2BhmsKNyhZof4IQJ%2FWv2xlZ9%2FWl5gnqKO0b4IM33c0zK7dT9oujExAc9Tv1tzcbmEXvX9Xrs%2Fenczwd4vz7Hi2yd7LarkyqKUoxuYSG8zCrePPHOhp7eqdQHkdlHV5%2Fn6p%2Bl2ARvfPH%2Bg8iwAahZZHXBXDJeBp7JoQdLCTWllwssyhqo%2BTb3OSANMyao9ed%2FYIVMVquVrL3lfOb0UeEmmQ%3D%3D%7Ctkp%3ABk9SR47u8L3mYQ | F9: 720 | H9: 293.08 | I9: 296.01 | J9: =I9+(I9*0.04) -> 307.8504 | K9: 225 | M9: DONE | N9: SI | P9: =F9-(J9+K9) -> 187.1496 | R9: SI | S9: FedEx: 396465905948 | T9: ENTREGADO A CLIENTE
A10: NO | B10: Migale | C10: COVER VOLVO | D10: 1 | E10: https://www.ebay.com/itm/114182300635?epid=1825189926&hash=item1a95cba3db:g:dFoAAOSwWPtekcc9&amdata=enc%3AAQAHAAAA4JrdX9uEUhHyuVzc44752o8kG3lPhqEEx2lIvydvC4uYRyeK6WB8RMwkC%2Fx9qt50tLZSrVnQuH7AAsw%2BLfIJLxIPI9wDizaFB4OCCy8O46qP55QL9PHz6ikjO3v7lzenqPwNffIxxPZ98wa8KZok%2FfsR%2FTUlGu4CcWlA8YqX4ppIAhBxdqHDcHCLTRidFUObqkATtLCoek1IU6%2Bx8%2FlDry82UYsjVdxHcrTRBsNuibxu8W602dHpFgjPVHIiBDyXjBY1XvmfgXdDk5KH0U8hIobC3Ak2XpBA3NhYekhhHvPg%7Ctkp%3ABk9SR_L4zLzmYQ | F10: 260 | G10: 45016 | H10: 87.12 | I10: 87.99 | J10: =I10+(I10*0.04) -> 91.5096 | K10: 80 | M10: DONE | N10: SI | P10: =F10-(J10+K10) -> 88.4904 | R10: SI | S10: FedEx:642099607710 | T10: ENTREGADO A CLIENTE
A11: NO | B11: Migale | C11: PARTS VOLVO | D11: 1 | E11: https://www.volvocarsoempartsdirect.com/checkout/aaa827035d449822ff600c6a73a71e65/shipping | F11: 2270 | H11: 1064.31 | I11: 1064.31 | J11: =I11+(I11*0.04) -> 1106.8824 | K11: 525 | M11: DONE | N11: SI | P11: =F11-(J11+K11) -> 638.1176 | R11: SI | S11: oldominion: 07114388254 | T11: ENTREGADO A CLIENTE
A12: NO | B12: Migale | C12: INTERFAZ VOLVO | D12: 1 | E12: https://www.amazon.com/-/es/Davitu-CarPlay-corriente-cable-5G0035222E/dp/B07M9RL1GD | F12: 150 | H12: 110.01 | I12: 111.11 | J12: =I12+(I12*0.04) -> 115.5544 | K12: 13 | M12: DONE | N12: SI | P12: =F12-(J12+K12) -> 21.4456 | R12: SI | S12: I sent you something from Amazon. You can track the delivery with this link. https://a.co/d/0h0HmIc | T12: ENTREGADO A CLIENTE
A13: NO | B13: Juan Rosso | C13: AKRAPOVIC | D13: 1 | E13: https://www.ebay.com/itm/115099474123 | F13: 0 | I13: 0 | J13: =I13+(I13*0.04) -> 0 | K13: 120 | M13: DONE | N13: SI | P13: =F13-(J13+K13) -> -120 | R13: SI | S13: DHL:5951504053 | T13: ENTREGADO A CLIENTE
A14: NO | B14: Axel Margossian | C14: Repuestos monopatin | D14: 1 | E14: n/a | F14: 220 | H14: 0 | I14: 0 | J14: =I14+(I14*0.04) -> 0 | K14: 180 | M14: DONE | N14: SI | P14: =F14-(J14+K14) -> 40 | R14: SI | S14: Fedex: 396683414634 | T14: ENTREGADO A CLIENTE
A15: NO | B15: Alan Olmedo | C15: Paragolpe M3 | D15: 1 | E15: https://www.ecstuning.com/b-ecs-parts/m3-replica-bumper-kit-non-integrated-lip/bm51009akt/ | F15: 1100 | G15: 45026 | H15: 368.98 | I15: 372.67 | J15: =I15+(I15*0.04) -> 387.5768 | K15: 480 | M15: DONE | N15: SI | P15: =F15-(J15+K15) -> 232.4232 | R15: SI | S15: Fedex: 466153718655061 | T15: ENTREGADO A CLIENTE
A16: NO | B16: Abel | C16: GFB Diverter T9356 | D16: 1 | E16: ebay | F16: 295 | H16: 117.7 | I16: 118.88 | J16: =I16+(I16*0.04) -> 123.6352 | K16: 30 | M16: DONE | N16: SI | P16: =F16-(J16+K16) -> 141.3648 | R16: SI | S16: USPS: 9400136106089681321152 | T16: ENTREGADO A CLIENTE
A17: NO | B17: Abel | C17: Filtro | D17: 1 | E17: https://www.ecstuning.com/b-afe-parts/pro-dry-s-air-filter/31-10226~afe/ | F17: 225 | H17: 105.41 | I17: 106.46 | J17: =I17+(I17*0.04) -> 110.7184 | K17: 40 | M17: DONE | N17: SI | P17: =F17-(J17+K17) -> 74.2816 | R17: SI | S17: Ups: 1Z404524YW90966922 | T17: ENTREGADO A CLIENTE
A18: NO | B18: Abel | C18: Pure turbo | D18: 1 | E18: https://www.pureturbos.com/product/bmw-n55-pure-stage-2/?attribute_pa_wastegateactuatortype=8a-electronicewg&attribute_pa_coredeposit-mustmatchturboyou=7b-ewgcore&attribute_pa_divertervalveupgrade=f2-no&attribute_pa_installationkit=f2-no&attribute_pa_highflowinlet=0f-f-seriesoption2 | F18: 5924 | H18: 3560 | I18: 3595.6 | J18: =I18+(I18*0.04) -> 3739.424 | K18: 640 | M18: DONE | N18: SI | P18: =F18-(J18+K18) -> 1544.576 | R18: SI | S18: UPS: 1ZWA81613597112914 | T18: ENTREGADO A CLIENTE
A19: NO | B19: Abel | C19: VRSF INTERCOOLER & CHARGE & OUTLET | D19: 1 | E19: https://www.vr-speed.com/checkout/order-received/100314774/?key=wc_order_7mfTX1ByiMW65&utm_nooverride=1 | F19: 2375 | G19: 45028 | H19: 778.97 | I19: 780 | J19: =I19+(I19*0.04) -> 811.2 | K19: 745 | M19: DONE | N19: SI | P19: =F19-(J19+K19) -> 818.8 | R19: SI | S19: fedex: 396974811467 | T19: ENTREGADO A CLIENTE
A20: NO | B20: Yani | C20: sensor Burger | D20: 1 | E20: https://burgertuning.com/products/jb4-3-5-bar-tmap-adapter?variant=2104148885528 | F20: 160 | G20: 45030 | H20: 107 | I20: 108.07 | J20: =I20+(I20*0.04) -> 112.3928 | K20: 13 | M20: DONE | N20: SI | P20: =F20-(J20+K20) -> 34.6072 | R20: SI | S20: usps: 9400111206214130779369 | T20: ENTREGADO A CLIENTE
A21: NO | B21: Abel | C21: Llantas M2 | D21: T | E21: https://www.getbmwparts.com/oem-parts/bmw-m-performance-frozen-gold-19-quot-style-763m-rim-9jx19-et-29-36118097287 | F21: 10120 | G21: 45029 | H21: 5103 | I21: 5154.68 | J21: =I21+(I21*0.04) -> 5360.8672 | K21: 2200 | M21: DONE | N21: SI | P21: =F21-(J21+K21) -> 2559.1328 | R21: SI | S21: UPS: 1Z283637A895717838 UPS: 1Z283637A898707647 / UPS: 1Z283637A895717838 UPS: 1Z283637A898707647 | T21: ENTREGADO A CLIENTE
A22: NO | B22: Abel | C22: Dorch Stage 2 | D22: 1 | E22: https://dorchengineering.com/checkout/order-received/3789?key=wc_order_sjD8AdGJvJLAb | F22: 2600 | G22: 45034 | H22: 1710.93 | I22: 1728.04 | J22: =I22+(I22*0.04) -> 1797.1616 | K22: 120 | M22: DONE | N22: SI | P22: =F22-(J22+K22) -> 682.8384 | R22: SI | S22: https://www.trackmyshipment.co/shipment-tracking/ESUS140777492 | T22: ENTREGADO A CLIENTE
A23: NO | B23: Mili mouso | C23: Bad bunny 7.5 us | D23: 1 | E23: https://www.goat.com/ | F23: 418 | G23: 45035 | H23: 261.62 | I23: 264.24 | J23: =I23+(I23*0.04) -> 274.8096 | K23: 100 | M23: DONE | N23: SI | P23: =F23-(J23+K23) -> 43.1904 | R23: SI | S23: https://track.parxl.com/PXLMY00323D02PU1 | T23: ENTREGADO A CLIENTE
A24: NO | B24: Abel | C24: Side Grill Trims | D24: 1 | E24: https://order.ebay.com/ord/show?/ViewPaymentStatus&purchaseOrderId=13-0996-606294#/ | F24: 422 | G24: 45036 | H24: 107 | I24: 108.07 | J24: =I24+(I24*0.04) -> 112.3928 | K24: 10 | M24: DONE | N24: SI | P24: =F24-(J24+K24) -> 299.6072 | R24: SI | S24: Latvia Post: RR917399666LV | T24: ENTREGADO A CLIENTE
A25: NO | B25: sergio | C25: Downpipe 240 g42 | D25: 1 | F25: 0 | G25: 45036 | H25: 390.99 | I25: 398.03 | J25: =I25+(I25*0.04) -> 413.9512 | K25: 0 | M25: DONE | N25: SI | P25: =F25-(J25+K25) -> -413.9512 | R25: SI | S25: https://trackshipment.shipstation.com/?branding_id=001d6731-0000-0000-1ebf-030000000000&carrier_code=ups&tracking_number=1ZA83W70DG25025584&order_number=MjI4Mzk4&postal_code=33166-2783&locale=en | T25: ENTREGADO A CLIENTE
A26: NO | B26: Rodri Freijedo | C26: Modulo encendido Honda | D26: 5 | E26: https://www.ebay.com/itm/134478644829 | F26: 605 | G26: 45040 | H26: 202.05 | I26: 218.35 | J26: 0 | K26: 40 | M26: DONE | N26: SI | P26: =F26-(J26+K26) -> 565 | R26: SI | S26: SpeedPAK: ES10023171321710001010001C0N | T26: ENTREGADO A CLIENTE
A27: NO | B27: Rodri Freijedo | C27: IACV Honda | D27: 5 | E27: https://www.ebay.com/itm/394507131153 | G27: 45040 | H27: 107.45 | I27: 118.48 | J27: 0 | K27: 20 | M27: DONE | N27: SI | P27: =F27-(J27+K27) -> -20 | R27: SI | S27: USPS: 9205590338269300665575 | T27: ENTREGADO A CLIENTE
A28: NO | B28: Rodri Freijedo | C28: CPK Sensor Honda | D28: 5 | E28: https://www.ebay.com/itm/191369133571 | G28: 45040 | H28: 74.6 | I28: 68.52 | J28: 0 | K28: 13 | M28: DONE | N28: SI | P28: =F28-(J28+K28) -> -13 | R28: SI | S28: FedEx: 397477801104 | T28: ENTREGADO A CLIENTE
A29: NO | B29: Abel | C29: BMW M2 1:18 | D29: 1 | E29: https://order.ebay.com/ord/show?orderId=10-09967-16454#/ | F29: 0 | H29: 172.37 | I29: 174.09 | J29: =I29+(I29*0.04) -> 181.0536 | K29: 100 | M29: DONE | N29: SI | P29: =F29-(J29+K29) -> -281.0536 | R29: SI | S29: Poste Italiane: RC179421742IT | T29: ENTREGADO A CLIENTE
A30: NO | B30: Abel | C30: Carbon fiber Mirrors & Exhaust tips | D30: 1 | E30: https://ind-distribution.com/6762364997/orders/8f77180929762682c4a74bab5cbbd6a8 | F30: 1199 | G30: 45042 | H30: 814.11 | I30: 822.25 | J30: =I30+(I30*0.04) -> 855.14 | K30: 200 | M30: DONE | N30: SI | P30: =F30-(J30+K30) -> 143.86 | R30: SI | S30: UPS: 1Z57Y1080371048015 - UPS: 1Z57Y1084270735380 (MIRRORS) | T30: ENTREGADO A CLIENTE
A31: NO | B31: Abel | C31: Riñones | D31: 1 | E31: https://autotecknic.com/26746278/orders/37b1e11fb56e0775086af1f0a7c31b51 | F31: 269 | G31: 45042 | H31: 171.48 | I31: 173.19 | J31: =I31+(I31*0.04) -> 180.1176 | K31: 40 | M31: DONE | N31: SI | P31: =F31-(J31+K31) -> 48.8824 | R31: SI | S31: UPS: 1Z8A34840317299430 | T31: ENTREGADO A CLIENTE
A32: NO | B32: Abel | C32: Capot CS | D32: 1 | E32: https://www.paypal.com/invoice/s/pay/INV2-ZPJ3-UVUH-2EG6-UPVY?v=1&utm_source=unp&utm_medium=email&utm_campaign=RT000426&utm_unptid=c884f738-df95-11ed-b2f8-3cecef47c1cd&ppid=RT000426&cnac=AR&rsta=en_US%28en-AR%29&cust=4JFB9WGZWMDB4&unptid=c884f738-df95-11ed-b2f8-3cecef47c1cd&calc=f392033bca259&unp_tpcid=invoice-buyer-payment-notification&page=main%3Aemail%3ART000426&pgrp=main%3Aemail&e=cl&mchn=em&s=ci&mail=sys&appVersion=1.161.0&xt=104038 | F32: 3050 | G32: 45036 | H32: 1352 | I32: 1352 | J32: =I32+(I32*0.04) -> 1406.08 | K32: 1470 | M32: DONE | N32: SI | P32: =F32-(J32+K32) -> 173.92 | R32: SI | S32: road runner: 611707217 | T32: ENTREGADO A CLIENTE
A33: NO | B33: Abel | C33: Aleron | D33: 1 | E33: https://www.aeroluxeautoboutique.com/commerce/orders/578a2dfb-2904-4c28-b500-4e3383b05d26 | F33: 789 | G33: 45042 | H33: 370 | I33: 370 | J33: =I33+(I33*0.04) -> 384.8 | K33: 120 | M33: DONE | N33: SI | P33: =F33-(J33+K33) -> 284.2 | R33: SI | S33: Fedex: 772013125060 | T33: ENTREGADO A CLIENTE
A34: NO | B34: Juan Papa | C34: ORDEN 1 Grande Repuestos M4 | D34: 1 | E34: https://www.getbmwparts.com/account/order?token=eyJ0eXAiOiJKV1QiLCJhbGciOiJIUzUxMiJ9.eyJvcmRlcl9udW1iZXIiOiI0NDEyMjcxOCIsInVzZXJfZW1haWwiOiJlbWlsaWFub0B0cmliZXNoaXBwaW5nLmNvbSJ9.csmHHYhXDjb5MDbQsrU24X0QXKD8eydtcXhM_Eh8qgvH0KQ7MChNrWSndrBee9w_UdEEiPd3K0-xjb3CgtDerA | F34: https://docs.google.com/spreadsheets/d/1krhqWKlIKFe6dnrTzcq6TyNLydmBDFXhPjvPEzYNR8M/edit#gid=0 | G34: 45041 | H34: 6350.33 | I34: 6413.83 | J34: =I34+(I34*0.04) -> 6670.3832 | K34: 2815 | M34: DONE | N34: SI | P34: =F34-(J34+K34) -> #VALUE! | R34: SI | S34: UPS: 089957302 | T34: ENTREGADO A CLIENTE
A35: NO | B35: Juan Papa | C35: ORDEN 2 Grande Repuestos M4 | D35: 1 | E35: https://www.getbmwparts.com/account/order?token=eyJ0eXAiOiJKV1QiLCJhbGciOiJIUzUxMiJ9.eyJvcmRlcl9udW1iZXIiOiI0NDEyMjcyMCIsInVzZXJfZW1haWwiOiJlbWlsaWFub0B0cmliZXNoaXBwaW5nLmNvbSJ9.4LQ2CZE8zPJLyim14VsFbs0Sv7FZRFfeKc6_tn86JplyrWAWbfMJXpThiPKXEUq7MnArZlptOShvECs24MQVbw | F35: https://docs.google.com/spreadsheets/d/1krhqWKlIKFe6dnrTzcq6TyNLydmBDFXhPjvPEzYNR8M/edit#gid=0 | G35: 45041 | H35: 829.83 | I35: 838.13 | J35: =I35+(I35*0.04) -> 871.6552 | K35: 360 | M35: DONE | N35: SI | P35: =F35-(J35+K35) -> #VALUE! | R35: SI | S35: UPS: 1ZCF3305A818812337 | T35: ENTREGADO A CLIENTE
A36: NO | B36: NERF | C36: Cepillos detail | D36: 1 | E36: amazon | F36: 0 | I36: 0 | J36: =I36+(I36*0.04) -> 0 | K36: 0 | M36: DONE | N36: SI | P36: =F36-(J36+K36) -> 0 | R36: SI | S36: https://www.amazon.com/progress-tracker/package/ref=ppx_yo_dt_b_track_package?_encoding=UTF8&itemId=pnnirskokptoqn&orderId=111-5981075-1761066&packageIndex=0&shipmentId=MhhrVvplf&vt=YOUR_ORDERS | T36: ENTREGADO A CLIENTE
A37: NO | B37: Tano | C37: Switch Mazda | D37: 1 | E37: https://www.amazon.com/gp/product/B09FSSTD34/ref=ppx_yo_dt_b_asin_title_o01_s00?ie=UTF8&psc=1 | F37: 100 | G37: 45040 | H37: 38.25 | I37: 38.63 | J37: =I37+(I37*0.04) -> 40.1752 | K37: 0 | M37: DONE | N37: SI | P37: =F37-(J37+K37) -> 59.8248 | R37: SI | S37: https://www.amazon.com/progress-tracker/package/ref=ppx_yo_dt_b_track_package?_encoding=UTF8&itemId=pmslpqhlrrkwqn&orderId=111-7212672-1937055&packageIndex=0&shipmentId=Dv3mBRNG7&vt=YOUR_ORDERS | T37: ENTREGADO A CLIENTE
A38: NO | B38: Alan Olmedo | C38: Intercooler VRSF | D38: 1 | E38: https://www.vr-speed.com/vrsf-intercooler-fmic-upgrade-kit-12-16-f20-f30-228i-m235i-328i-335i-428i-435i-n20-n55.html | F38: 1150 | G38: 45052 | H38: 379.99 | I38: 383.79 | J38: =I38+(I38*0.04) -> 399.1416 | K38: 495 | M38: DONE | N38: SI | P38: =F38-(J38+K38) -> 255.8584 | R38: SI | S38: Fedex: 398020036489 | T38: ENTREGADO A CLIENTE
A39: NO | B39: Alan Olmedo | C39: Filtro ECS | D39: 1 | E39: https://www.ecstuning.com/Cart/Receipt-652996050/?customerID=2679329 | F39: 90 | G39: 45054 | H39: 35.81 | I39: 36.17 | J39: =I39+(I39*0.04) -> 37.6168 | K39: 40 | M39: DONE | N39: SI | P39: =F39-(J39+K39) -> 12.3832 | R39: SI | S39: Ups: 1Z404524YW99159663 | T39: ENTREGADO A CLIENTE
A40: NO | B40: Anibal Bento | C40: Sensor de fase land rover | D40: 1 | E40: https://www.roverparts.com/cart/receipt.cfm?id=5187696&uuid=BF3D1404-4416-49AF-892352589BCF5921 | F40: 335 | G40: 45054 | H40: 203.9 | I40: 205.94 | J40: =I40+(I40*0.04) -> 214.1776 | K40: 0 | M40: DONE | N40: SI | P40: =F40-(J40+K40) -> 120.8224 | R40: SI | S40: Usps: 9400116902200601765773 | T40: ENTREGADO A CLIENTE
...

Sheet STOCK
I1: SUGERIDOS
A2: ID | B2: FECHA | C2: MARCA | D2: ITEM | E2: VARIANTE | F2: CANTIDAD | G2: DISPONIBLES | H2: COSTO TOTAL POR UNIDAD | I2: GANANCIA | J2: PRECIO LISTA | K2: GANANCIA EMI | L2: PRECIO EMI | M2: GANANCIA TALLER | N2: PRECIO TALLER | O2: VENTAS (ID) | P2: CONCAT
A3: 625 | B3: 45949 | C3: CTS | D3: DOWNPIPE | E3: B58 | F3: 4 | G3: 0 | H3: =176.1448+(4.5*50) -> 401.1448 | I3: 0.69515 | J3: =H3+(H3*I3) -> 680.00061 | K3: 0.5 | L3: =H3+(H3*K3) -> 601.7172 | M3: 0.55 | N3: =H3+(H3*M3) -> 621.77444 | O3: =CONCATENATE('SEGUIMIENTO COMPRAS TRIBE'!B665, ", ",'SEGUIMIENTO COMPRAS TRIBE'!B695,", ",'SEGUIMIENTO COMPRAS TRIBE'!B701,", ",'SEGUIMIENTO COMPRAS TRIBE'!B707) -> Emiliano Righetti, Emiliano Righetti, Emiliano Righetti, Emiliano Righetti | P3: =CONCATENATE(C3," ",D3," ",E3) -> CTS DOWNPIPE B58
A4: 625, 649 | B4: 45949 | C4: CTS | D4: DOWNPIPE | E4: S58 | F4: 4 | G4: 1 | H4: =518.96+(5.25*50) -> 781.46 | I4: 0.69515 | J4: =H4+(H4*I4) -> 1324.6919 | K4: 0.35 | L4: =H4+(H4*K4) -> 1054.971 | M4: 0.55 | N4: =H4+(H4*M4) -> 1211.263 | O4: =CONCATENATE('SEGUIMIENTO COMPRAS TRIBE'!B662, ", ", 'SEGUIMIENTO COMPRAS TRIBE'!B663) -> Santiago Ventana, Emiliano Alcaide | P4: =CONCATENATE(C4," ",D4," ",E4) -> CTS DOWNPIPE S58
A5: 624 | B5: 45949 | C5: Infinity Design | D5: INTAKE | E5: B58 G42 | F5: 1 | G5: 0 | H5: 1223.07 | I5: 0.4 | J5: =H5+(H5*I5) -> 1712.298 | K5: 0.2 | L5: =H5+(H5*K5) -> 1467.684 | M5: 0.25 | N5: =H5+(H5*M5) -> 1528.8375 | O5: =CONCATENATE('SEGUIMIENTO COMPRAS TRIBE'!B708, ", ") -> Emiliano Righetti, | P5: =CONCATENATE(C5," ",D5," ",E5) -> Infinity Design INTAKE B58 G42
A6: 623 | B6: 45950 | C6: NGK | D6: Bujias | E6: B58/S58 | F6: 10 | G6: 6 | H6: 98.2 | I6: 0.525 | J6: =H6+(H6*I6) -> 149.755 | K6: 0.325 | L6: =H6+(H6*K6) -> 130.115 | M6: 0.425 | N6: =H6+(H6*M6) -> 139.935 | O6: =CONCATENATE('SEGUIMIENTO COMPRAS TRIBE'!B661, ", ",'SEGUIMIENTO COMPRAS TRIBE'!B664 , ", ", 'SEGUIMIENTO COMPRAS TRIBE'!B679,", ",'SEGUIMIENTO COMPRAS TRIBE'!B682) -> Mauro Lerda, Santiago Ventana, Emiliano Righetti, Javier Pergamino | P6: =CONCATENATE(C6," ",D6," ",E6) -> NGK Bujias B58/S58
A7: 676 | B7: 45973 | C7: Infinity Design | D7: INTAKE | E7: S58 | F7: 2 | G7: 1 | H7: 2225 | I7: 0.4 | J7: =H7+(H7*I7) -> 3115 | K7: 0.2 | L7: =H7+(H7*K7) -> 2670 | M7: 0.25 | N7: =H7+(H7*M7) -> 2781.25 | O7: =CONCATENATE('SEGUIMIENTO COMPRAS TRIBE'!B687, ", ") -> Santiago Ventana, | P7: =CONCATENATE(C7," ",D7," ",E7) -> Infinity Design INTAKE S58
A8: 696 | B8: 46001 | C8: Generica | D8: Rejillas | E8: M2 G87 | F8: 5 | G8: 4 | H8: 80.4 | I8: 0.5 | J8: =H8+(H8*I8) -> 120.6 | K8: 0.25 | L8: =H8+(H8*K8) -> 100.5 | M8: 0.37 | N8: =H8+(H8*M8) -> 110.148 | O8: =CONCATENATE('SEGUIMIENTO COMPRAS TRIBE'!B765, ", ") -> Emiliano Alcaide, | P8: =CONCATENATE(C8," ",D8," ",E8) -> Generica Rejillas M2 G87
A9: 713 | B9: 46001 | C9: Infinity Design | D9: INTAKE | E9: B58 G42 | F9: 3 | G9: 3 | H9: 1158 | I9: 0.479 | J9: =H9+(H9*I9) -> 1712.682 | K9: 0.265 | L9: =H9+(H9*K9) -> 1464.87 | M9: 0.32 | N9: =H9+(H9*M9) -> 1528.56
A10: 719 | B10: 46001 | C10: CTS | D10: DOWNPIPE | E10: B58 | F10: 9 | G10: 8 | H10: 398 | I10: 0.6952 | J10: =H10+(H10*I10) -> 674.6896 | K10: 0.5 | L10: =H10+(H10*K10) -> 597 | M10: 0.55 | N10: =H10+(H10*M10) -> 616.9 | O10: =CONCATENATE('SEGUIMIENTO COMPRAS TRIBE'!B767, ", ") -> Emiliano Righetti, | P10: =CONCATENATE(C10," ",D10," ",E10) -> CTS DOWNPIPE B58
I11: 0 | J11: =H11+(H11*I11) -> 0 | K11: 0 | L11: =H11+(H11*K11) -> 0 | M11: 0 | N11: =H11+(H11*M11) -> 0
I12: 0 | J12: =H12+(H12*I12) -> 0 | K12: 0 | L12: =H12+(H12*K12) -> 0 | M12: 0 | N12: =H12+(H12*M12) -> 0
I13: 0 | J13: =H13+(H13*I13) -> 0 | K13: 0 | L13: =H13+(H13*K13) -> 0 | M13: 0 | N13: =H13+(H13*M13) -> 0
I14: 0 | J14: =H14+(H14*I14) -> 0 | K14: 0 | L14: =H14+(H14*K14) -> 0 | M14: 0 | N14: =H14+(H14*M14) -> 0
C15: Caja al 26/02/2026 (dinero disponible) | D15: =5217.98-3150 -> 2067.98 | I15: 0 | J15: =H15+(H15*I15) -> 0 | K15: 0 | L15: =H15+(H15*K15) -> 0 | M15: 0 | N15: =H15+(H15*M15) -> 0
I16: 0 | J16: =H16+(H16*I16) -> 0 | K16: 0 | L16: =H16+(H16*K16) -> 0 | M16: 0 | N16: =H16+(H16*M16) -> 0
I17: 0 | J17: =H17+(H17*I17) -> 0 | K17: 0 | L17: =H17+(H17*K17) -> 0 | M17: 0 | N17: =H17+(H17*M17) -> 0
I18: 0 | J18: =H18+(H18*I18) -> 0 | K18: 0 | L18: =H18+(H18*K18) -> 0 | M18: 0 | N18: =H18+(H18*M18) -> 0
I19: 0 | J19: =H19+(H19*I19) -> 0 | K19: 0 | L19: =H19+(H19*K19) -> 0 | M19: 0 | N19: =H19+(H19*M19) -> 0
I20: 0 | J20: =H20+(H20*I20) -> 0 | K20: 0 | L20: =H20+(H20*K20) -> 0 | M20: 0 | N20: =H20+(H20*M20) -> 0
I21: 0 | J21: =H21+(H21*I21) -> 0 | K21: 0 | L21: =H21+(H21*K21) -> 0 | M21: 0 | N21: =H21+(H21*M21) -> 0
I22: 0 | J22: =H22+(H22*I22) -> 0 | K22: 0 | L22: =H22+(H22*K22) -> 0 | M22: 0 | N22: =H22+(H22*M22) -> 0
I23: 0 | J23: =H23+(H23*I23) -> 0 | K23: 0 | L23: =H23+(H23*K23) -> 0 | M23: 0 | N23: =H23+(H23*M23) -> 0
I24: 0 | J24: =H24+(H24*I24) -> 0 | K24: 0 | L24: =H24+(H24*K24) -> 0 | M24: 0 | N24: =H24+(H24*M24) -> 0
I25: 0 | J25: =H25+(H25*I25) -> 0 | K25: 0 | L25: =H25+(H25*K25) -> 0 | M25: 0 | N25: =H25+(H25*M25) -> 0
I26: 0 | J26: =H26+(H26*I26) -> 0 | K26: 0 | L26: =H26+(H26*K26) -> 0 | M26: 0 | N26: =H26+(H26*M26) -> 0
I27: 0 | J27: =H27+(H27*I27) -> 0 | K27: 0 | L27: =H27+(H27*K27) -> 0 | M27: 0 | N27: =H27+(H27*M27) -> 0
... I33: 0 | J33: =H33+(H33*I33) -> 0 | K33: 0 | L33: =H33+(H33*K33) -> 0 | M33: 0 | N33: =H33+(H33*M33) -> 0

Sheet REPRO
A1: FECHA | B1: CODIGO | C1: COSTO | D1: PRECIO | E1: USADA | F1: CLIENTE | G1: Ganancia | H1: SALDADO COSTO DE LICENCIA | I1: SALDADAS US | J1: ABONADA A | K1: ABONADA POR CLIENTE/EMI
A2: 45236 | B2: 984D005F-4B74-4F97-857D-D74086F4AC5D | C2: 424 | D2: N/A | E2: TRUE | F2: LUIS BIG TURBO | G2: n/a | H2: SI | I2: SI | J2: FEDE | K2: SI | L2: Your permanent license discount code is:
A3: 45237 | B3: 99BEF756-B80B-4725-8146-79C956DF9DEB | C3: 424 | D3: 600 | E3: TRUE | F3: EMILIANO RIGHETTI | G3: =D3-C3 -> 176 | H3: SI | I3: SI | J3: FEDE | K3: SI | M3: BMA30WSD
A4: 45238 | B4: E631335F-0B21-4A8E-A47C-E811AAB4A46F | C4: 424 | D4: 600 | E4: TRUE | F4: EMILIANO RIGHETTI | G4: =D4-C4 -> 176 | H4: SI | I4: SI | J4: FEDE | K4: SI | L4: Your permanent hardware discount code is:
A5: 45239 | B5: 036C7E28-606A-4003-A006-BEB9808765F2 | C5: 424 | D5: 750 | E5: TRUE | F5: 140i AZUL RICKY | G5: =D5-C5 -> 326 | H5: SI | I5: SI | J5: FEDE | K5: SI | M5: BMA15HDW
A6: 45240 | B6: B16454C8-EBDC-4736-B6FF-0451A2A46838 | C6: 424 | D6: 750 | E6: TRUE | F6: 328I N20 RICKY | G6: =D6-C6 -> 326 | H6: SI | I6: SI | J6: FEDE | K6: SI
A7: 45433 | B7: MHD | C7: 187 | D7: 400 | E7: TRUE | F7: 13I N54 RICKY | G7: =D7-C7 -> 213 | H7: SI | I7: SI | J7: FEDE | K7: SI
A8: 45436 | B8: B20BBDF1-4AD1-4EA6-8AC0-813F35535038 | C8: 416.5 | D8: 700 | E8: TRUE | F8: X4 RICKY | G8: =D8-C8 -> 283.5 | H8: SI | I8: SI | J8: FEDE | K8: SI
A9: 45513 | B9: 6A88B923-7F95-4CAF-8BE0-100B16DB32AD | C9: =416.5+(416.5*0.04) -> 433.16 | D9: N/A | E9: TRUE | F9: Hernan Franchina 240 G42 | G9: n/a | H9: SI | I9: SI | J9: FEDE | K9: SI | M9: COSTO UNLOCK+LICENCIA | N9: =700+375 -> 1075
A10: 45525 | B10: 43584210-8F92-4028-A936-9F9E711866A4 | C10: =416.5+(416.5*0.04) -> 433.16 | D10: N/A | E10: TRUE | F10: Ferzilla | G10: n/a | H10: SI | I10: SI | J10: FEDE | K10: SI
A11: 45525 | B11: F3ECAD8D-0144-46B2-B19A-C0D3C4B6C872 | C11: =50+(50*0.04) -> 52 | D11: 52 | E11: TRUE | F11: EMILIANO RIGHETTI | G11: =D11-C11 -> 0 | H11: SI | I11: SI | J11: FEDE | K11: SI | M11: PRECIOS de referencia
A12: 45530 | B12: ABA1D9AD-C427-4EA7-8D40-72FA121BFDA7 | C12: =416.5+(416.5*0.04) -> 433.16 | D12: 567 | E12: TRUE | F12: EMILIANO RIGHETTI | G12: =D12-C12 -> 133.84 | H12: SI | I12: SI | J12: FEDE | K12: SI | M12: ITEM | N12: PRECIO LISTA | O12: DESC EMI | P12: PRECIO EMI | Q12: DESC TALLER | R12: PRECIO TALLER
A13: 45624 | B13: 5489F26F-C8DE-4917-B1A9-565AADF515A4 | C13: =416.5+(416.5*0.04) -> 433.16 | D13: 567 | E13: TRUE | F13: EMILIANO RIGHETTI | G13: =D13-C13 -> 133.84 | H13: SI | I13: SI | J13: FEDE | K13: SI | M13: REPRO FEMTO NON-M | N13: 2500 | O13: 0.06 | P13: =N13-(N13*O13) -> 2350 | Q13: 0.04 | R13: =N13-(N13*Q13) -> 2400
A14: 45301 | B14: 6508DE4-E37F-4025-835E-1457B06ABE32 | C14: 416.5 | D14: 700 | E14: TRUE | F14: 120I B48 RICKY | G14: =D14-C14 -> 283.5 | H14: SI | I14: SI | J14: FEDE | K14: SI | M14: REPRO FEMTO M | N14: 2700 | O14: 0.06 | P14: =N14-(N14*O14) -> 2538 | Q14: 0.04 | R14: =N14-(N14*Q14) -> 2592
A15: 45301 | B15: F2213172-CB14-4CF1-9100-448E2B3BA568 | C15: 416.5 | D15: 0 | E15: TRUE | F15: GEROCHIVO CLAVADO | G15: =D15-C15 -> -416.5 | H15: SI | I15: SI | J15: FEDE | K15: SI | M15: REPRO BM3 NON-M | N15: 700 | O15: 0.19 | P15: =N15-(N15*O15) -> 567 | Q15: 0.1 | R15: =N15-(N15*Q15) -> 630
A16: 45700 | B16: 32253872-D3EE-4035-9C1E-C9BEE46046FE | C16: =416.5+(416.5*0.04) -> 433.16 | D16: 567 | E16: TRUE | F16: NICO MAGGI | G16: =D16-C16 -> 133.84 | H16: SI | I16: SI | J16: FEDE | K16: SI | M16: REPRO BM3 M | N16: 700 | O16: 0.19 | P16: =N16-(N16*O16) -> 567 | Q16: 0.1 | R16: =N16-(N16*Q16) -> 630
A17: 45737 | B17: E8B88CD9-6A01-4166-9848-D0F3551AAC2D | C17: 0 | D17: 0 | E17: TRUE | F17: EMILIANO RIGHETTI - UNLOCK G42 - MANUEL VAZQUEZ | G17: 0 | H17: SI | I17: SI | J17: FEDE | K17: SI
A18: 45741 | B18: E871F0DC-A1C7-47B7-84D4-3C0F0E121C9C | C18: =433.16 -> 433.16 | D18: 567 | E18: TRUE | F18: EMILIANO RIGHETTI - JONY LALLITA | G18: =D18-C18 -> 133.84 | H18: SI | I18: SI | J18: FEDE | K18: SI | M18: PROPUESTA
A19: 45785 | B19: 4BBB1328-5F13-4C14-A1E5-9B827A146BF4 | C19: =433.16 -> 433.16 | D19: 567 | E19: TRUE | F19: EMILIANO RIGHETTI - robertonicolaspierce@gmail.com - AD616TJ | G19: =D19-C19 -> 133.84 | H19: SI | I19: SI | J19: FEDE | K19: SI | M19: REPRO FEMTO AMBAS | N19: 2200 | O19: 0.06 | P19: =N19-(N19*O19) -> 2068 | Q19: 0.04 | R19: =N19-(N19*Q19) -> 2112
A20: 45791 | B20: 45AAD44D-33A3-4D4A-8C2D-1414980D2641 | C20: =433.16 -> 433.16 | D20: 567 | E20: TRUE | F20: EMILIANO RIGHETTI - thiagomoro09@gmail.com - AD842VD | G20: =D20-C20 -> 133.84 | H20: SI | I20: SI | J20: FEDE | K20: SI | M20: REPRO FEMTO COMBO | N20: 1500 | O20: 0.06 | P20: =N20-(N20*O20) -> 1410 | Q20: 0.04 | R20: =N20-(N20*Q20) -> 1440
A21: 45793 | B21: 8C79CD09-9235-4B09-A46C-597B2BE0380F | C21: =433.16 -> 433.16 | D21: 567 | E21: TRUE | F21: EMILIANO RIGHETTI - uri.galanis@gmail.com - ac674ah | G21: =D21-C21 -> 133.84 | H21: SI | I21: SI | J21: FEDE | K21: SI
A22: 45849 | B22: 09055F98-597C-4EB0-98D3-490321A0B51B | C22: =433.16 -> 433.16 | D22: 550 | E22: TRUE | F22: ALAN OLMEDO - Tito comparato - N20 | G22: =D22-C22 -> 116.84 | H22: SI | I22: SI | J22: FEDE | K22: SI
A23: 45854 | B23: A35DD6B7-8C98-4D86-A3D8-54F7ED4FB944 | C23: 433.16 | D23: 567 | E23: TRUE | F23: EMILIANO RIGHETTI - maxiplaza80@gmail.com - AB529LV | G23: =D23-C23 -> 133.84 | H23: SI | I23: SI | J23: FEDE | K23: SI
A24: 45855 | B24: ECEDD916-DF51-43DB-8B07-76BE500831C9 | C24: 0 | D24: n/a | E24: TRUE | F24: Juli Lerda - M2 - Repro G Series | G24: 0 | H24: SI | I24: SI | J24: FEDE | K24: SI
A25: 45859 | B25: 990DF998-7293-4376-A82F-D717694EBB81 | C25: 626.5 | D25: 763 | E25: TRUE | F25: EMILIANO RIGHETTI - muruzabal77@gmail.com - AD381DQ | G25: =D25-C25 -> 136.5 | H25: SI | I25: SI | J25: FEDE | K25: SI
A26: 45860 | B26: 583B2FF6-2075-412B-82A3-C867BB1ECE13 | C26: 433.16 | D26: 567 | E26: TRUE | F26: EMILIANO RIGHETTI - b48 430 | G26: =D26-C26 -> 133.84 | H26: SI | I26: SI | J26: FEDE | K26: SI
A27: 45862 | B27: 11696C04-21F2-446A-8F3E-ACF5D22857BD | C27: 0 | D27: n/a | E27: TRUE | F27: Veleta - M2 G87 - Repro G series | G27: 0 | H27: SI | I27: SI | J27: FEDE | K27: SI
A28: 45869 | B28: LICENCE | C28: 325 | D28: 325 | E28: TRUE | F28: 135i e82 | G28: =D28-C28 -> 0 | H28: SI | I28: SI | J28: FEDE | K28: SI
A29: 45882 | B29: F7B8F744-8582-4745-A6E6-EFD6DCC23873 | C29: 0 | D29: Unlock | E29: TRUE | F29: Tomas Graben - 240i G42 - Repro G Series | G29: 0 | H29: SI | I29: SI | J29: FEDE | K29: SI
A30: 45883 | B30: 43074D0A-9772-443D-BEEB-29B2AA083E6D | C30: 0 | D30: Unlock | E30: TRUE | F30: RASPAGLIESI - M2 G87 - Repro G Series | G30: 0 | H30: SI | I30: SI | J30: FEDE | K30: SI
A31: 45887 | B31: F82798C3-CE44-4098-95A1-E612D494B1FA | C31: 433.16 | D31: 567 | E31: TRUE | F31: Emiliano Righetti - 335 - | G31: =D31-C31 -> 133.84 | H31: SI | I31: SI | J31: FEDE | K31: SI
A32: 45895 | B32: C5232B9C-1AEB-41FB-BC28-F073E0B0ACF1 | C32: 433.16 | D32: 567 | E32: TRUE | F32: Emiliano Righetti - 140 - santiszmulewicz@gmail.com - AC584RQ | G32: =D32-C32 -> 133.84 | H32: SI | I32: SI | J32: FEDE | K32: SI
A33: 45898 | B33: 3001338A-74C1-41BB-A7C0-89B5129D0C97 | C33: 433.16 | D33: 567 | E33: TRUE | F33: Emiliano Righetti - Chef - | G33: =D33-C33 -> 133.84 | H33: SI | I33: SI | J33: FEDE | K33: SI
A34: 45912 | B34: 56704954-3714-4498-BE2E-E289B7267BE3 | C34: 433.16 | D34: 567 | E34: TRUE | F34: Emiliano Righetti - 140 - Losfiore@gmail.com | G34: =D34-C34 -> 133.84 | H34: SI | I34: SI | J34: FEDE | K34: SI
A35: 45923 | B35: A5DA8F44-2822-40CE-8E3C-3B6CD24F7F05 | C35: 0 | D35: Unlock | E35: TRUE | F35: Leonardo Abdine - M240i G42 - Repro G Series | G35: - | H35: SI | I35: SI | J35: FEDE | K35: SI
A36: 45923 | B36: 4FDC25B4-4824-4DEA-8463-F977D413FC13 | C36: 0 | D36: Unlock | E36: TRUE | F36: Brian Lee - M240i G42 - Repro G Series | G36: - | H36: SI | I36: SI | J36: FEDE | K36: SI
A37: 45929 | B37: 8896ACAC-8656-4D01-9398-EEC7F805C870 | C37: 433.16 | D37: 567 | E37: TRUE | F37: Emiliano Righetti - Lucasjamus@hotmail.com - AE743LU | G37: =D37-C37 -> 133.84 | H37: SI | I37: SI | J37: FEDE | K37: SI
A38: 45933 | B38: C181B552-C0EB-4727-900B-BC05F765FD74 | C38: 60 | D38: 110 | E38: TRUE | F38: Emiliano Righetti - OTS Map Bundle - frigorificonazca@yahoo.com.ar | G38: =D38-C38 -> 50 | H38: SI | I38: SI | J38: FEDE | K38: SI
A39: 45924 | B39: CS Flash | C39: 307 | D39: 497.5 | E39: TRUE | F39: M2 Nacho Caparros | G39: =D39-C39 -> 190.5 | H39: SI | I39: SI | J39: FEDE | K39: SI
A40: 45924 | B40: CS Steering & Audio profile | C40: 178 | D40: 178 | E40: TRUE | F40: M2 Emiliano Righetti | G40: =D40-C40 -> 0 | H40: SI | I40: SI | J40: FEDE | K40: SI
...

Sheet PAQUETES
A3: COSTO APROX FEMTO UNLOCK | B3: =REPRO!N9 -> 1075 | E3: GANANCIAS
A4: COSTO BAJADA B58 | B4: =STOCK!H10 -> 398 | E4: LISTA | F4: TALLER | G4: EMI
A5: COSTO BAJADA S58 | B5: =STOCK!H4 -> 781.46 | E5: 0.4 | F5: 0.3 | G5: 0.2
A6: COSTO INFINITY B58 | B6: =STOCK!H9 -> 1158
A7: COSTO INFINITY S58 | B7: =STOCK!H7 -> 2225
A8: COSTO BUJIAS TITAN | B8: =STOCK!H6 -> 98.2
A12: COSTO | B12: PAQUETE B58 | C12: LISTA | D12: TALLER | E12: EMI | H12: PAQUETE S58
A13: BAJADA | B13: =B4 -> 398 | C13: =B13*E5 -> 159.2 | D13: =B13*F5 -> 119.4 | E13: =B13*G5 -> 79.6 | H13: =B5 -> 781.46
A14: INTAKE | B14: =B6 -> 1158 | C14: =B14*E5 -> 463.2 | D14: =B14*F5 -> 347.4 | E14: =B14*G5 -> 231.6 | H14: =B7 -> 2225
A15: BUJIAS | B15: =B8 -> 98.2 | C15: =B15*E5 -> 39.28 | D15: =B15*F5 -> 29.46 | E15: =B15*G5 -> 19.64 | H15: =B8 -> 98.2
A16: REPRO | B16: =B3 -> 1075 | C16: =B16*E5 -> 430 | D16: =B16*F5 -> 322.5 | E16: =B16*G5 -> 215 | H16: =B3 -> 1075
A17: TOTAL | B17: =SUM(B13:B16) -> 2729.2 | C17: =SUM(C13:C16) -> 1091.68 | D17: =SUM(D13:D16) -> 818.76 | E17: =SUM(E13:E16) -> 545.84 | H17: =SUM(H13:H16) -> 4179.66
A19: SIN INTAKE | B19: =SUM(B13,B15,B16) -> 1571.2 | H19: =SUM(H13,H15,H16) -> 1954.66

Sheet DETALLE DE PAGOS ENVIOS A APCAR
A1: ENVIOS Y PAGOS
A3: ITEM | B3: ENVIO ABONADO | C3: PAGADO POR | D3: SALDADO? | F3: GANANCIA SELECCIONADA
A4: PARTES GETBMW M3 E36 | B4: 280 | C4: FEDE | D4: SI | F4: GANANCIA TOTAL
A5: PARTES ECS M3 E36 | B5: 160 | C5: FEDE | D5: SI
A6: JUNTA COMETIC | B6: 80 | C6: FEDE | D6: SI | F6: OTRAS CONSIDERACIONES
A7: CHAPON WRX | B7: 160 | C7: FEDE | D7: SI | F7: ITEM | G7: VALOR | H7: OBSERVACIONES
A8: GUARDAPLAST WRX | B8: 40 | C8: FEDE Y NAHUE | D8: SI | F8: DINERO PARA SALDO COMPRAS | G8: 2000 | H8: ENTREGADO A NAHUE 16/07/2024
A9: PASARUEDAS WRX | B9: 40 | C9: NAHUE | D9: SI
A10: BOMBA WALBRO | B10: 40 | C10: FEDE | D10: SI
A11: PASTILLAS HAWK | B11: 40 | C11: FEDE | D11: SI
A12: TECLADO NAHUE | B12: N/A | C12: N/A | D12: SI
A13: ESCAPE AKRAPOVIC | B13: 120 | C13: FEDE | D13: SI
A14: PARTES VOLVO GENUINE | B14: 525 | C14: FEDE | D14: SI | F14: PAGOS CUESTIONES ADMINISTRATIVAS TRIBE SHIPPING
A15: OPTICA VOLVO DER | B15: 225 | C15: FEDE | D15: SI | F15: ITEM | G15: VALOR | H15: OBSERVACIONES
A16: OPTICA VOLVO IZQ | B16: 225 | C16: FEDE | D16: SI | F16: GASTOS PUBLICIDAD Y VARIOS SALDADOS A JUNIO-2024 | G16: OK
A17: INTERFAZ VOLVO | B17: 13 | C17: FEDE | D17: SI | F17: Renovacion de dominio | G17: 22.17 | H17: pagado por nahue 16/07/2024
A18: PLASTICO VOLVO EBAY | B18: 80 | C18: FEDE | D18: SI | F18: BimmerFest | G18: 67 | H18: 17/10/2025 transfe Fede
A19: PARTES MARGOSIAN 1ER PARTE | B19: 180 | C19: FEDE | D19: SI | F19: BimmerFest | G19: 138 | H19: 03/12/2025 transfe Fede
A20: PARAGOLPE M3 E36 | B20: 480 | C20: FEDE | D20: SI | F20: Pago cartel TribeShipping para bimmerfest | G20: 25 | H20: abonado el 11/12/2025 por fede
A21: FILTRO M2 ABEL | B21: 40 | C21: FEDE | D21: SI | F21: Renovacion de dominio | G21: 22.17 | H21: pagado por nahue 24 jun 2025
A22: VRSF M2 ABEL | B22: 745 | C22: FEDE | D22: SI | F22: Google Workspace desde Julio 24 a Enero 26 | G22: 358.04 | H22: pagado por nahue
A23: SENSOR N20 YANI | B23: 13 | C23: FEDE | D23: SI | F23: Via Cargo Downpipe Raptor | G23: 10 | H23: pagado por nahue
A24: LLANTAS M2 ABEL | B24: 2200 | C24: FEDE | D24: SI | F24: PUBLICIDAD IG | G24: 51.73 | H24: pagado por nahue
A25: SENSORES HONDA X5 | B25: 13 | C25: FEDE | D25: SI
A26: AUTITO ESCALA M2 | B26: 100 | C26: FEDE | D26: SI
A27: ZAPATILLAS MILAGROS MOUSO | B27: 100 | C27: FEDE | D27: SI
A28: DIVERTER M2 ABEL | B28: 30 | C28: FEDE | D28: SI
A29: SIDEMARKERS M2 ABEL | B29: 10 | C29: FEDE | D29: SI
A30: IACV HONDA | B30: 20 | C30: FEDE | D30: SI
A31: COLITAS M2 ABEL | B31: 80 | C31: FEDE | D31: SI
A32: RIÑONES M2 ABEL | B32: 40 | C32: FEDE | D32: SI
A33: MODULOS HONDA X5 | B33: 40 | C33: NAHUE | D33: SI
A34: ALERON M2 ABEL | B34: 120 | C34: NAHUE | D34: SI
A35: ORDEN GRANDE M4 JUAN PAPA | B35: 2815 | C35: NAHUE | D35: SI
A36: CEPILLOS DETAIL NAHUE | B36: N/A | C36: N/A | D36: SI
A37: SWITCH MAZDA TANO | B37: N/A | C37: N/A | D37: SI
A38: INTERCOOLER VRSF OLMEDO | B38: 495 | C38: NAHUE | D38: SI
A39: REPUESTOS MARGOSIAN CAMARO | B39: 155 | C39: NAHUE | D39: SI
A40: ROPA JUAN PAPA | B40: 225 | C40: FEDE | D40: SI
A41: DISCOS TRASEROS M3 | B41: 630 | C41: FEDE | D41: SI
...
